2023-03-19 17:16:00,190 INFO    MainThread:20468 [wandb_setup.py:_flush():76] Configure stats pid to 20468
2023-03-19 17:16:00,190 INFO    MainThread:20468 [wandb_setup.py:_flush():76] Loading settings from /Users/siddharth/.config/wandb/settings
2023-03-19 17:16:00,190 INFO    MainThread:20468 [wandb_setup.py:_flush():76] Loading settings from /Users/siddharth/Downloads/ma-gym 2/wandb/settings
2023-03-19 17:16:00,190 INFO    MainThread:20468 [wandb_setup.py:_flush():76] Loading settings from environment variables: {}
2023-03-19 17:16:00,190 INFO    MainThread:20468 [wandb_setup.py:_flush():76] Applying setup settings: {'_disable_service': False}
2023-03-19 17:16:00,190 INFO    MainThread:20468 [wandb_setup.py:_flush():76] Inferring run settings from compute environment: {'program_relpath': 'minimal-marl/idqn.py', 'program': 'minimal-marl/idqn.py'}
2023-03-19 17:16:00,190 INFO    MainThread:20468 [wandb_init.py:_log_setup():506] Logging user logs to /Users/siddharth/Downloads/ma-gym 2/wandb/run-20230319_171600-ndo65mlh/logs/debug.log
2023-03-19 17:16:00,191 INFO    MainThread:20468 [wandb_init.py:_log_setup():507] Logging internal logs to /Users/siddharth/Downloads/ma-gym 2/wandb/run-20230319_171600-ndo65mlh/logs/debug-internal.log
2023-03-19 17:16:00,191 INFO    MainThread:20468 [wandb_init.py:init():546] calling init triggers
2023-03-19 17:16:00,191 INFO    MainThread:20468 [wandb_init.py:init():552] wandb.init called with sweep_config: {}
config: {'algo': 'idqn', 'env_name': 'ma_gym:Switch2-v1', 'lr': 0.0005, 'batch_size': 32, 'gamma': 0.99, 'buffer_limit': 50000, 'log_interval': 20, 'max_episodes': 30000, 'max_epsilon': 0.9, 'min_epsilon': 0.1, 'test_episodes': 5, 'warm_up_steps': 2000, 'update_iter': 10, 'monitor': False}
2023-03-19 17:16:00,191 INFO    MainThread:20468 [wandb_init.py:init():602] starting backend
2023-03-19 17:16:00,191 INFO    MainThread:20468 [wandb_init.py:init():606] setting up manager
2023-03-19 17:16:00,197 INFO    MainThread:20468 [backend.py:_multiprocessing_setup():106] multiprocessing start_methods=spawn,fork,forkserver, using: spawn
2023-03-19 17:16:00,200 INFO    MainThread:20468 [wandb_init.py:init():613] backend started and connected
2023-03-19 17:16:00,204 INFO    MainThread:20468 [wandb_init.py:init():701] updated telemetry
2023-03-19 17:16:00,244 INFO    MainThread:20468 [wandb_init.py:init():741] communicating run to backend with 60.0 second timeout
2023-03-19 17:16:28,801 INFO    Thread-1  :20468 [retry.py:__call__():172] Retry attempt failed:
Traceback (most recent call last):
  File "/Users/siddharth/opt/anaconda3/envs/openai/lib/python3.8/site-packages/urllib3/connection.py", line 174, in _new_conn
    conn = connection.create_connection(
  File "/Users/siddharth/opt/anaconda3/envs/openai/lib/python3.8/site-packages/urllib3/util/connection.py", line 95, in create_connection
    raise err
  File "/Users/siddharth/opt/anaconda3/envs/openai/lib/python3.8/site-packages/urllib3/util/connection.py", line 85, in create_connection
    sock.connect(sa)
socket.timeout: timed out

During handling of the above exception, another exception occurred:

Traceback (most recent call last):
  File "/Users/siddharth/opt/anaconda3/envs/openai/lib/python3.8/site-packages/urllib3/connectionpool.py", line 703, in urlopen
    httplib_response = self._make_request(
  File "/Users/siddharth/opt/anaconda3/envs/openai/lib/python3.8/site-packages/urllib3/connectionpool.py", line 386, in _make_request
    self._validate_conn(conn)
  File "/Users/siddharth/opt/anaconda3/envs/openai/lib/python3.8/site-packages/urllib3/connectionpool.py", line 1042, in _validate_conn
    conn.connect()
  File "/Users/siddharth/opt/anaconda3/envs/openai/lib/python3.8/site-packages/urllib3/connection.py", line 363, in connect
    self.sock = conn = self._new_conn()
  File "/Users/siddharth/opt/anaconda3/envs/openai/lib/python3.8/site-packages/urllib3/connection.py", line 179, in _new_conn
    raise ConnectTimeoutError(
urllib3.exceptions.ConnectTimeoutError: (<urllib3.connection.HTTPSConnection object at 0x7fbffbd7fcd0>, 'Connection to api.wandb.ai timed out. (connect timeout=10)')

During handling of the above exception, another exception occurred:

Traceback (most recent call last):
  File "/Users/siddharth/opt/anaconda3/envs/openai/lib/python3.8/site-packages/requests/adapters.py", line 489, in send
    resp = conn.urlopen(
  File "/Users/siddharth/opt/anaconda3/envs/openai/lib/python3.8/site-packages/urllib3/connectionpool.py", line 787, in urlopen
    retries = retries.increment(
  File "/Users/siddharth/opt/anaconda3/envs/openai/lib/python3.8/site-packages/urllib3/util/retry.py", line 592, in increment
    raise MaxRetryError(_pool, url, error or ResponseError(cause))
urllib3.exceptions.MaxRetryError: HTTPSConnectionPool(host='api.wandb.ai', port=443): Max retries exceeded with url: /graphql (Caused by ConnectTimeoutError(<urllib3.connection.HTTPSConnection object at 0x7fbffbd7fcd0>, 'Connection to api.wandb.ai timed out. (connect timeout=10)'))

During handling of the above exception, another exception occurred:

Traceback (most recent call last):
  File "/Users/siddharth/opt/anaconda3/envs/openai/lib/python3.8/site-packages/wandb/sdk/lib/retry.py", line 131, in __call__
    result = self._call_fn(*args, **kwargs)
  File "/Users/siddharth/opt/anaconda3/envs/openai/lib/python3.8/site-packages/wandb/sdk/internal/internal_api.py", line 243, in execute
    return self.client.execute(*args, **kwargs)  # type: ignore
  File "/Users/siddharth/opt/anaconda3/envs/openai/lib/python3.8/site-packages/wandb/vendor/gql-0.2.0/wandb_gql/client.py", line 52, in execute
    result = self._get_result(document, *args, **kwargs)
  File "/Users/siddharth/opt/anaconda3/envs/openai/lib/python3.8/site-packages/wandb/vendor/gql-0.2.0/wandb_gql/client.py", line 60, in _get_result
    return self.transport.execute(document, *args, **kwargs)
  File "/Users/siddharth/opt/anaconda3/envs/openai/lib/python3.8/site-packages/wandb/vendor/gql-0.2.0/wandb_gql/transport/requests.py", line 38, in execute
    request = requests.post(self.url, **post_args)
  File "/Users/siddharth/opt/anaconda3/envs/openai/lib/python3.8/site-packages/requests/api.py", line 115, in post
    return request("post", url, data=data, json=json, **kwargs)
  File "/Users/siddharth/opt/anaconda3/envs/openai/lib/python3.8/site-packages/requests/api.py", line 59, in request
    return session.request(method=method, url=url, **kwargs)
  File "/Users/siddharth/opt/anaconda3/envs/openai/lib/python3.8/site-packages/requests/sessions.py", line 587, in request
    resp = self.send(prep, **send_kwargs)
  File "/Users/siddharth/opt/anaconda3/envs/openai/lib/python3.8/site-packages/requests/sessions.py", line 701, in send
    r = adapter.send(request, **kwargs)
  File "/Users/siddharth/opt/anaconda3/envs/openai/lib/python3.8/site-packages/requests/adapters.py", line 553, in send
    raise ConnectTimeout(e, request=request)
requests.exceptions.ConnectTimeout: HTTPSConnectionPool(host='api.wandb.ai', port=443): Max retries exceeded with url: /graphql (Caused by ConnectTimeoutError(<urllib3.connection.HTTPSConnection object at 0x7fbffbd7fcd0>, 'Connection to api.wandb.ai timed out. (connect timeout=10)'))
2023-03-19 17:16:42,440 WARNING MainThread:20468 [wandb_init.py:init():1165] interrupted
Traceback (most recent call last):
  File "/Users/siddharth/opt/anaconda3/envs/openai/lib/python3.8/site-packages/wandb/sdk/wandb_init.py", line 1144, in init
    run = wi.init()
  File "/Users/siddharth/opt/anaconda3/envs/openai/lib/python3.8/site-packages/wandb/sdk/wandb_init.py", line 744, in init
    result = run_init_handle.wait(
  File "/Users/siddharth/opt/anaconda3/envs/openai/lib/python3.8/site-packages/wandb/sdk/lib/mailbox.py", line 283, in wait
    found, abandoned = self._slot._get_and_clear(timeout=wait_timeout)
  File "/Users/siddharth/opt/anaconda3/envs/openai/lib/python3.8/site-packages/wandb/sdk/lib/mailbox.py", line 130, in _get_and_clear
    if self._wait(timeout=timeout):
  File "/Users/siddharth/opt/anaconda3/envs/openai/lib/python3.8/site-packages/wandb/sdk/lib/mailbox.py", line 126, in _wait
    return self._event.wait(timeout=timeout)
  File "/Users/siddharth/opt/anaconda3/envs/openai/lib/python3.8/threading.py", line 558, in wait
    signaled = self._cond.wait(timeout)
  File "/Users/siddharth/opt/anaconda3/envs/openai/lib/python3.8/threading.py", line 306, in wait
    gotit = waiter.acquire(True, timeout)
KeyboardInterrupt
