2023-03-19 17:16:00,204 INFO    StreamThr :20578 [internal.py:wandb_internal():87] W&B internal server running at pid: 20578, started at: 2023-03-19 17:16:00.203633
2023-03-19 17:16:00,205 DEBUG   HandlerThread:20578 [handler.py:handle_request():144] handle_request: status
2023-03-19 17:16:00,206 INFO    WriterThread:20578 [datastore.py:open_for_write():85] open: /Users/siddharth/Downloads/ma-gym 2/wandb/run-20230319_171600-ndo65mlh/run-ndo65mlh.wandb
2023-03-19 17:16:00,210 DEBUG   SenderThread:20578 [sender.py:send():336] send: header
2023-03-19 17:16:00,245 DEBUG   SenderThread:20578 [sender.py:send():336] send: run
2023-03-19 17:16:05,267 DEBUG   HandlerThread:20578 [handler.py:handle_request():144] handle_request: keepalive
2023-03-19 17:16:10,286 DEBUG   HandlerThread:20578 [handler.py:handle_request():144] handle_request: keepalive
2023-03-19 17:16:15,306 DEBUG   HandlerThread:20578 [handler.py:handle_request():144] handle_request: keepalive
2023-03-19 17:16:20,401 DEBUG   HandlerThread:20578 [handler.py:handle_request():144] handle_request: keepalive
2023-03-19 17:16:25,421 DEBUG   HandlerThread:20578 [handler.py:handle_request():144] handle_request: keepalive
2023-03-19 17:16:30,441 DEBUG   HandlerThread:20578 [handler.py:handle_request():144] handle_request: keepalive
2023-03-19 17:16:33,596 INFO    SenderThread:20578 [retry.py:__call__():172] Retry attempt failed:
Traceback (most recent call last):
  File "/Users/siddharth/opt/anaconda3/envs/openai/lib/python3.8/site-packages/urllib3/connection.py", line 174, in _new_conn
    conn = connection.create_connection(
  File "/Users/siddharth/opt/anaconda3/envs/openai/lib/python3.8/site-packages/urllib3/util/connection.py", line 95, in create_connection
    raise err
  File "/Users/siddharth/opt/anaconda3/envs/openai/lib/python3.8/site-packages/urllib3/util/connection.py", line 85, in create_connection
    sock.connect(sa)
socket.timeout: timed out

During handling of the above exception, another exception occurred:

Traceback (most recent call last):
  File "/Users/siddharth/opt/anaconda3/envs/openai/lib/python3.8/site-packages/urllib3/connectionpool.py", line 703, in urlopen
    httplib_response = self._make_request(
  File "/Users/siddharth/opt/anaconda3/envs/openai/lib/python3.8/site-packages/urllib3/connectionpool.py", line 386, in _make_request
    self._validate_conn(conn)
  File "/Users/siddharth/opt/anaconda3/envs/openai/lib/python3.8/site-packages/urllib3/connectionpool.py", line 1042, in _validate_conn
    conn.connect()
  File "/Users/siddharth/opt/anaconda3/envs/openai/lib/python3.8/site-packages/urllib3/connection.py", line 363, in connect
    self.sock = conn = self._new_conn()
  File "/Users/siddharth/opt/anaconda3/envs/openai/lib/python3.8/site-packages/urllib3/connection.py", line 179, in _new_conn
    raise ConnectTimeoutError(
urllib3.exceptions.ConnectTimeoutError: (<urllib3.connection.HTTPSConnection object at 0x7f8232d820d0>, 'Connection to api.wandb.ai timed out. (connect timeout=10)')

During handling of the above exception, another exception occurred:

Traceback (most recent call last):
  File "/Users/siddharth/opt/anaconda3/envs/openai/lib/python3.8/site-packages/requests/adapters.py", line 489, in send
    resp = conn.urlopen(
  File "/Users/siddharth/opt/anaconda3/envs/openai/lib/python3.8/site-packages/urllib3/connectionpool.py", line 787, in urlopen
    retries = retries.increment(
  File "/Users/siddharth/opt/anaconda3/envs/openai/lib/python3.8/site-packages/urllib3/util/retry.py", line 592, in increment
    raise MaxRetryError(_pool, url, error or ResponseError(cause))
urllib3.exceptions.MaxRetryError: HTTPSConnectionPool(host='api.wandb.ai', port=443): Max retries exceeded with url: /graphql (Caused by ConnectTimeoutError(<urllib3.connection.HTTPSConnection object at 0x7f8232d820d0>, 'Connection to api.wandb.ai timed out. (connect timeout=10)'))

During handling of the above exception, another exception occurred:

Traceback (most recent call last):
  File "/Users/siddharth/opt/anaconda3/envs/openai/lib/python3.8/site-packages/wandb/sdk/lib/retry.py", line 131, in __call__
    result = self._call_fn(*args, **kwargs)
  File "/Users/siddharth/opt/anaconda3/envs/openai/lib/python3.8/site-packages/wandb/sdk/internal/internal_api.py", line 243, in execute
    return self.client.execute(*args, **kwargs)  # type: ignore
  File "/Users/siddharth/opt/anaconda3/envs/openai/lib/python3.8/site-packages/wandb/vendor/gql-0.2.0/wandb_gql/client.py", line 52, in execute
    result = self._get_result(document, *args, **kwargs)
  File "/Users/siddharth/opt/anaconda3/envs/openai/lib/python3.8/site-packages/wandb/vendor/gql-0.2.0/wandb_gql/client.py", line 60, in _get_result
    return self.transport.execute(document, *args, **kwargs)
  File "/Users/siddharth/opt/anaconda3/envs/openai/lib/python3.8/site-packages/wandb/vendor/gql-0.2.0/wandb_gql/transport/requests.py", line 38, in execute
    request = requests.post(self.url, **post_args)
  File "/Users/siddharth/opt/anaconda3/envs/openai/lib/python3.8/site-packages/requests/api.py", line 115, in post
    return request("post", url, data=data, json=json, **kwargs)
  File "/Users/siddharth/opt/anaconda3/envs/openai/lib/python3.8/site-packages/requests/api.py", line 59, in request
    return session.request(method=method, url=url, **kwargs)
  File "/Users/siddharth/opt/anaconda3/envs/openai/lib/python3.8/site-packages/requests/sessions.py", line 587, in request
    resp = self.send(prep, **send_kwargs)
  File "/Users/siddharth/opt/anaconda3/envs/openai/lib/python3.8/site-packages/requests/sessions.py", line 701, in send
    r = adapter.send(request, **kwargs)
  File "/Users/siddharth/opt/anaconda3/envs/openai/lib/python3.8/site-packages/requests/adapters.py", line 553, in send
    raise ConnectTimeout(e, request=request)
requests.exceptions.ConnectTimeout: HTTPSConnectionPool(host='api.wandb.ai', port=443): Max retries exceeded with url: /graphql (Caused by ConnectTimeoutError(<urllib3.connection.HTTPSConnection object at 0x7f8232d820d0>, 'Connection to api.wandb.ai timed out. (connect timeout=10)'))
2023-03-19 17:16:35,466 DEBUG   HandlerThread:20578 [handler.py:handle_request():144] handle_request: keepalive
2023-03-19 17:16:40,496 DEBUG   HandlerThread:20578 [handler.py:handle_request():144] handle_request: keepalive
2023-03-19 17:16:42,458 DEBUG   HandlerThread:20578 [handler.py:handle_request():144] handle_request: shutdown
2023-03-19 17:16:42,459 INFO    HandlerThread:20578 [handler.py:finish():842] shutting down handler
2023-03-19 17:16:43,023 INFO    WriterThread:20578 [datastore.py:close():298] close: /Users/siddharth/Downloads/ma-gym 2/wandb/run-20230319_171600-ndo65mlh/run-ndo65mlh.wandb
2023-03-19 17:18:08,616 INFO    SenderThread:20578 [dir_watcher.py:__init__():219] watching files in: /Users/siddharth/Downloads/ma-gym 2/wandb/run-20230319_171600-ndo65mlh/files
2023-03-19 17:18:08,617 INFO    SenderThread:20578 [sender.py:_start_run_threads():1078] run started: ndo65mlh with start time 1679271360.200844
2023-03-19 17:18:08,618 INFO    SenderThread:20578 [sender.py:finish():1504] shutting down sender
2023-03-19 17:18:08,618 INFO    SenderThread:20578 [dir_watcher.py:finish():365] shutting down directory watcher
2023-03-19 17:18:09,623 INFO    SenderThread:20578 [dir_watcher.py:finish():395] scan: /Users/siddharth/Downloads/ma-gym 2/wandb/run-20230319_171600-ndo65mlh/files
2023-03-19 17:18:09,624 INFO    SenderThread:20578 [dir_watcher.py:finish():409] scan save: /Users/siddharth/Downloads/ma-gym 2/wandb/run-20230319_171600-ndo65mlh/files/config.yaml config.yaml
2023-03-19 17:18:09,625 INFO    SenderThread:20578 [file_pusher.py:finish():164] shutting down file pusher
2023-03-19 17:18:09,625 INFO    SenderThread:20578 [file_pusher.py:join():169] waiting for file pusher
2023-03-19 17:18:10,325 INFO    wandb-upload_0:20578 [upload_job.py:push():138] Uploaded file /Users/siddharth/Downloads/ma-gym 2/wandb/run-20230319_171600-ndo65mlh/files/config.yaml
